Workbook

Sheet Product_Audit
A1: SKU | B1: Category | C1: Product Name | D1: Flavor | E1: Ingredients | F1: Allergens | G1: Nutrition Facts Status | H1: Net Weight | I1: Serving Size | J1: Storage Temperature | K1: Shelf Life | L1: Country of Sale | M1: Packaging Type | N1: Barcode Status | O1: Product Description Status | P1: Mandatory Attributes Status | Q1: Launch Status | R1: Validation Result
A2: FD-TUB-1001 | B2: Ice Cream Tubs | C2: Chocolate Ice Cream | D2: Chocolate | E2: Milk, cream, sugar, skim milk powder, glucose syrup, emulsifier (mono- and diglycerides of fatty acids), stabilizers (locust bean gum, guar gum, carrageenan), cocoa powder (4%), natural flavor | F2: Milk | G2: Complete | H2: 473 mL | I2: 2/3 cup (95 g) | J2: -18°C | K2: 12 months | L2: United States | M2: Paperboard tub with PP lid | N2: Missing | O2: Complete | P2: Incomplete | Q2: Blocked | R2: Blocked: Barcode missing
A3: FD-TUB-1002 | B3: Ice Cream Tubs | C3: Vanilla Bean Ice Cream | D3: Vanilla | E3: Milk, cream, sugar, skim milk powder, glucose syrup, emulsifier (mono- and diglycerides of fatty acids), stabilizers (locust bean gum, guar gum, carrageenan), egg yolk, natural vanilla extract, ground vanilla bean | F3: Milk, Eggs | G3: Complete | H3: 500 mL | I3: 2/3 cup (250 g) | J3: -18°C | K3: 18 months | L3: Brazil | M3: Paperboard tub with PP lid | N3: Valid | O3: Complete | P3: Complete | Q3: Warning | R3: Warning: Serving size inconsistent
A4: FD-TUB-1003 | B4: Ice Cream Tubs | C4: Strawberry Ice Cream | D4: Strawberry | E4: Milk, cream, sugar, skim milk powder, glucose syrup, emulsifier (mono- and diglycerides of fatty acids), stabilizers (locust bean gum, guar gum, carrageenan), strawberries (12%), strawberry puree, beet juice concentrate (color), natural flavor | F4: Milk | G4: Complete | H4: 1 L | I4: 2/3 cup (95 g) | J4: -18°C | K4: 18 months | L4: United States | M4: Paperboard tub with PP lid | N4: Valid | O4: Complete | P4: Complete | Q4: Approved | R4: Approved: All mandatory data complete
A5: FD-TUB-1004 | B5: Ice Cream Tubs | C5: Pistachio Gelato | D5: Pistachio | E5: Whole milk, sugar, cream, skim milk powder, dextrose, stabilizers (locust bean gum, guar gum), pistachio paste (8%), roasted pistachios, salt | F5: Milk, Tree Nuts (Pistachio) | G5: Complete | H5: 500 mL | I5: 2/3 cup (100 g) | J5: -18°C | K5: 15 months | L5: United States | M5: Paperboard tub with PP lid | N5: Valid | O5: Complete | P5: Complete | Q5: Approved | R5: Approved: All mandatory data complete
A6: FD-TUB-1005 | B6: Ice Cream Tubs | C6: Salted Caramel Ice Cream | D6: Salted Caramel | E6: Milk, cream, sugar, skim milk powder, glucose syrup, emulsifier (mono- and diglycerides of fatty acids), stabilizers (locust bean gum, guar gum, carrageenan), caramel sauce (sugar, glucose syrup, cream, butter, salt) (10%), sea salt | F6: Milk | G6: Complete | H6: 473 mL | I6: 2/3 cup (95 g) | J6: -18°C | K6: 18 months | L6: United States | M6: Paperboard tub with PP lid | N6: Valid | O6: Complete | P6: Complete | Q6: Approved | R6: Approved: All mandatory data complete
A7: FD-TUB-1006 | B7: Ice Cream Tubs | C7: Cookies & Cream Ice Cream | D7: Cookies & Cream | E7: Milk, cream, sugar, skim milk powder, glucose syrup, emulsifier (mono- and diglycerides of fatty acids), stabilizers (locust bean gum, guar gum, carrageenan), chocolate cookie pieces (wheat flour, sugar, palm oil, cocoa powder, soy lecithin, sodium bicarbonate, salt) (9%), natural vanilla flavor | F7: Milk, Wheat, Soy | G7: Complete | H7: 500 mL | I7: 2/3 cup (95 g) | J7: -18°C | L7: United States | M7: Paperboard tub with PP lid | N7: Valid | O7: Complete | P7: Complete | Q7: Warning | R7: Warning: Shelf life missing
A8: FD-TUB-1007 | B8: Ice Cream Tubs | C8: Mint Chocolate Chip Ice Cream | D8: Mint Chocolate Chip | E8: Milk, cream, sugar, skim milk powder, glucose syrup, emulsifier (mono- and diglycerides of fatty acids), stabilizers (locust bean gum, guar gum, carrageenan), dark chocolate chips (sugar, cocoa mass, cocoa butter, soy lecithin) (7%), natural peppermint oil, spirulina extract (color) | F8: Milk, Soy | G8: Complete | H8: 1 L | I8: 2/3 cup (250 g) | J8: -18°C | K8: 12 months | L8: Canada | M8: Paperboard tub with PP lid | N8: Valid | O8: Complete | P8: Complete | Q8: Warning | R8: Warning: Serving size inconsistent
A9: FD-TUB-1008 | B9: Ice Cream Tubs | C9: Coffee Ice Cream | D9: Coffee | E9: Milk, cream, sugar, skim milk powder, glucose syrup, emulsifier (mono- and diglycerides of fatty acids), stabilizers (locust bean gum, guar gum, carrageenan), coffee extract (2%), soluble coffee | F9: Milk | G9: Complete | H9: 1.5 L | I9: 2/3 cup (95 g) | J9: -18°C | K9: 15 months | L9: United States | M9: Paperboard tub with PP lid | N9: Valid | O9: Incomplete | P9: Complete | Q9: Warning | R9: Warning: Product description incomplete
A10: FD-TUB-1009 | B10: Ice Cream Tubs | C10: Hazelnut Gelato | D10: Hazelnut | E10: Whole milk, sugar, cream, skim milk powder, dextrose, stabilizers (locust bean gum, guar gum), hazelnut paste (10%), roasted hazelnut pieces | F10: Milk, Tree Nuts (Hazelnut) | G10: Complete | H10: 500 mL | I10: 2/3 cup (100 g) | J10: -20°C | K10: 12 months | L10: Canada | M10: Paperboard tub with PP lid | N10: Valid | O10: Complete | P10: Complete | Q10: Approved | R10: Approved: All mandatory data complete
A11: FD-TUB-1010 | B11: Ice Cream Tubs | C11: Dulce de Leche Ice Cream | D11: Dulce de Leche | E11: Milk, cream, sugar, skim milk powder, glucose syrup, emulsifier (mono- and diglycerides of fatty acids), stabilizers (locust bean gum, guar gum, carrageenan), dulce de leche swirl (sweetened condensed milk, sugar, sodium bicarbonate) (12%) | G11: Complete | H11: 500 mL | I11: 2/3 cup (95 g) | J11: -18°C | K11: 12 months | L11: Canada | M11: Paperboard tub with PP lid | N11: Valid | O11: Complete | P11: Incomplete | Q11: Blocked | R11: Blocked: Missing allergen declaration
A12: FD-TUB-1011 | B12: Ice Cream Tubs | C12: Rocky Road Ice Cream | D12: Rocky Road | E12: Milk, cream, sugar, skim milk powder, glucose syrup, emulsifier (mono- and diglycerides of fatty acids), stabilizers (locust bean gum, guar gum, carrageenan), cocoa powder, mini marshmallows (sugar, glucose syrup, water, gelatin, natural flavor), roasted almonds (5%), chocolate flakes (sugar, cocoa mass, cocoa butter, soy lecithin) | G12: Complete | H12: 1 L | I12: 2/3 cup (95 g) | J12: -18°C | K12: 18 months | L12: United States | M12: Paperboard tub with PP lid | N12: Valid | O12: Complete | P12: Incomplete | Q12: Blocked | R12: Blocked: Missing allergen declaration
A13: FD-TUB-1012 | B13: Ice Cream Tubs | C13: Butter Pecan Ice Cream | D13: Butter Pecan | E13: Milk, cream, sugar, skim milk powder, glucose syrup, emulsifier (mono- and diglycerides of fatty acids), stabilizers (locust bean gum, guar gum, carrageenan), buttered pecans (pecans, butter, salt) (8%), natural butter flavor | F13: Milk, Tree Nuts (Pecan) | G13: Complete | H13: 1.5 L | I13: 2/3 cup (95 g) | J13: -18°C | K13: 15 months | L13: United States | M13: Paperboard tub with PP lid | N13: Valid | O13: Complete | P13: Complete | Q13: Approved | R13: Approved: All mandatory data complete
A14: FD-TUB-1013 | B14: Ice Cream Tubs | C14: Mango Sorbet | D14: Mango | E14: Water, mango puree (35%), sugar, glucose syrup, lemon juice concentrate, stabilizer (locust bean gum) | F14: None | G14: Missing | H14: 473 mL | I14: 2/3 cup (110 g) | J14: -18°C | K14: 18 months | L14: Brazil | M14: Paperboard tub with PP lid | N14: Valid | O14: Complete | P14: Incomplete | Q14: Blocked | R14: Blocked: Missing Nutrition Facts
A15: FD-TUB-1014 | B15: Ice Cream Tubs | C15: Lemon Sorbet | D15: Lemon | E15: Water, sugar, lemon juice (18%), glucose syrup, lemon zest, stabilizer (guar gum) | F15: None | G15: Complete | H15: 473 mL | I15: 2/3 cup (110 g) | J15: -18°C | K15: 18 months | L15: Brazil | M15: Paperboard tub with PP lid | N15: Valid | O15: Complete | P15: Complete | Q15: Approved | R15: Approved: All mandatory data complete
A16: FD-TUB-1015 | B16: Ice Cream Tubs | C16: Raspberry Sorbet | D16: Raspberry | E16: Water, raspberry puree (30%), sugar, glucose syrup, lemon juice concentrate, stabilizer (locust bean gum) | F16: None | G16: Complete | H16: 473 mL | I16: 2/3 cup (110 g) | J16: -18°C | K16: 18 months | L16: Brazil | M16: Paperboard tub with PP lid | N16: Valid | O16: Complete | P16: Complete | Q16: Approved | R16: Approved: All mandatory data complete
A17: FD-TUB-1016 | B17: Ice Cream Tubs | C17: Coconut Non-Dairy Frozen Dessert | D17: Coconut | E17: Coconut cream (40%), water, sugar, tapioca syrup, toasted coconut flakes, stabilizers (guar gum, locust bean gum), sea salt | F17: None | G17: Complete | H17: 473 mL | I17: 2/3 cup (250 g) | J17: -18°C | K17: 15 months | L17: United States | M17: Paperboard tub with PP lid | N17: Valid | O17: Complete | P17: Complete | Q17: Warning | R17: Warning: Serving size inconsistent
A18: FD-TUB-1017 | B18: Ice Cream Tubs | C18: Stracciatella Gelato | D18: Stracciatella | E18: Whole milk, sugar, cream, skim milk powder, dextrose, stabilizers (locust bean gum, guar gum), dark chocolate shavings (cocoa mass, sugar, cocoa butter, soy lecithin) (8%) | F18: Milk, Soy | G18: Complete | H18: 500 mL | I18: 2/3 cup (100 g) | J18: -18°C | K18: 12 months | L18: United Kingdom | M18: Paperboard tub with PP lid | N18: Valid | O18: Complete | P18: Complete | Q18: Approved | R18: Approved: All mandatory data complete
A19: FD-TUB-1018 | B19: Ice Cream Tubs | C19: Tiramisu Gelato | D19: Tiramisu | E19: Whole milk, sugar, cream, skim milk powder, dextrose, stabilizers (locust bean gum, guar gum), mascarpone (cream, citric acid), ladyfinger pieces (wheat flour, sugar, eggs) soaked in coffee, cocoa powder, Marsala wine | F19: Milk, Wheat, Eggs | G19: Complete | H19: 500 mL | I19: 2/3 cup (100 g) | J19: -18°C | K19: 12 months | L19: United States | M19: Paperboard tub with PP lid | N19: Valid | O19: Complete | P19: Complete | Q19: Approved | R19: Approved: All mandatory data complete
A20: FD-TUB-1019 | B20: Ice Cream Tubs | C20: Cookie Dough Ice Cream | D20: Cookie Dough | E20: Milk, cream, sugar, skim milk powder, glucose syrup, emulsifier (mono- and diglycerides of fatty acids), stabilizers (locust bean gum, guar gum, carrageenan), cookie dough pieces (wheat flour, brown sugar, butter, chocolate chips [sugar, cocoa mass, cocoa butter, soy lecithin], salt) (12%), natural vanilla flavor | F20: Milk, Wheat, Soy | G20: Complete | H20: 1 L | I20: 2/3 cup (95 g) | J20: -18°C | K20: 12 months | L20: United Kingdom | M20: Paperboard tub with PP lid | N20: Valid | O20: Complete | P20: Complete | Q20: Approved | R20: Approved: All mandatory data complete
A21: FD-TUB-1020 | B21: Ice Cream Tubs | C21: Peanut Butter Cup Ice Cream | D21: Peanut Butter | E21: Milk, cream, sugar, skim milk powder, glucose syrup, emulsifier (mono- and diglycerides of fatty acids), stabilizers (locust bean gum, guar gum, carrageenan), peanut butter swirl (peanuts, sugar, salt) (8%), peanut butter cups (milk chocolate [sugar, cocoa butter, milk powder, cocoa mass, soy lecithin], peanuts) (6%) | F21: Milk, Peanuts, Soy | G21: Missing | H21: 1.5 L | I21: 2/3 cup (95 g) | J21: -18°C | K21: 18 months | L21: Canada | M21: Paperboard tub with PP lid | N21: Valid | O21: Complete | P21: Incomplete | Q21: Blocked | R21: Blocked: Missing Nutrition Facts
A22: FD-TUB-1021 | B22: Ice Cream Tubs | C22: Double Chocolate Brownie Ice Cream | D22: Chocolate Brownie | E22: Milk, cream, sugar, skim milk powder, glucose syrup, emulsifier (mono- and diglycerides of fatty acids), stabilizers (locust bean gum, guar gum, carrageenan), cocoa powder, brownie pieces (sugar, wheat flour, eggs, butter, cocoa powder) (9%), chocolate fudge swirl (sugar, glucose syrup, cocoa powder) | F22: Milk, Wheat, Eggs | G22: Complete | H22: 473 mL | I22: 2/3 cup (95 g) | J22: -20°C | K22: 15 months | L22: United Kingdom | M22: Paperboard tub with PP lid | N22: Valid | O22: Complete | P22: Complete | Q22: Approved | R22: Approved: All mandatory data complete
A23: FD-TUB-1022 | B23: Ice Cream Tubs | C23: Neapolitan Ice Cream | D23: Chocolate / Vanilla / Strawberry | E23: Milk, cream, sugar, skim milk powder, glucose syrup, emulsifier (mono- and diglycerides of fatty acids), stabilizers (locust bean gum, guar gum, carrageenan), cocoa powder, strawberry puree (4%), natural vanilla flavor, beet juice concentrate (color) | F23: Milk | G23: Complete | H23: 500 mL | I23: 2/3 cup (95 g) | J23: -18°C | K23: 18 months | L23: Brazil | M23: Paperboard tub with PP lid | N23: Valid | O23: Complete | P23: Complete | Q23: Approved | R23: Approved: All mandatory data complete
A24: FD-TUB-1023 | B24: Ice Cream Tubs | C24: Rum Raisin Ice Cream | D24: Rum Raisin | E24: Milk, cream, sugar, skim milk powder, glucose syrup, emulsifier (mono- and diglycerides of fatty acids), stabilizers (locust bean gum, guar gum, carrageenan), rum-soaked raisins (raisins, rum) (8%), natural rum flavor | F24: Milk | G24: Complete | H24: 1 L | I24: 2/3 cup (95 g) | J24: -18°C | K24: 12 months | L24: Brazil | M24: Paperboard tub with PP lid | N24: Valid | O24: Complete | P24: Complete | Q24: Approved | R24: Approved: All mandatory data complete
A25: FD-TUB-1024 | B25: Ice Cream Tubs | C25: Black Cherry Ice Cream | D25: Black Cherry | E25: Milk, cream, sugar, skim milk powder, glucose syrup, emulsifier (mono- and diglycerides of fatty acids), stabilizers (locust bean gum, guar gum, carrageenan), black cherries (10%), cherry puree, elderberry juice concentrate (color) | F25: Milk | G25: Complete | H25: 1.5 L | I25: 2/3 cup (95 g) | J25: -18°C | K25: 15 months | L25: United States | N25: Valid | O25: Complete | P25: Complete | Q25: Warning | R25: Warning: Packaging information missing
A26: FD-TUB-1025 | B26: Ice Cream Tubs | C26: Matcha Green Tea Ice Cream | D26: Matcha | E26: Milk, cream, sugar, skim milk powder, glucose syrup, emulsifier (mono- and diglycerides of fatty acids), stabilizers (locust bean gum, guar gum, carrageenan), matcha green tea powder (2%) | F26: Milk | G26: Complete | H26: 473 mL | I26: 2/3 cup (95 g) | J26: -18°C | K26: 15 months | L26: United States | M26: Paperboard tub with PP lid | N26: Valid | O26: Complete | P26: Complete | Q26: Approved | R26: Approved: All mandatory data complete
A27: FD-TUB-1026 | B27: Ice Cream Tubs | C27: Cinnamon Churro Ice Cream | D27: Cinnamon Churro | E27: Milk, cream, sugar, skim milk powder, glucose syrup, emulsifier (mono- and diglycerides of fatty acids), stabilizers (locust bean gum, guar gum, carrageenan), ground cinnamon, churro pieces (wheat flour, sugar, sunflower oil, cinnamon, salt) (6%) | F27: Milk, Wheat | G27: Complete | H27: 500 mL | I27: 2/3 cup (95 g) | K27: 15 months | M27: Paperboard tub with PP lid | N27: Valid | O27: Complete | P27: Incomplete | Q27: Blocked | R27: Blocked: Mandatory attributes missing
A28: FD-TUB-1027 | B28: Ice Cream Tubs | C28: Blueberry Cheesecake Ice Cream | D28: Blueberry Cheesecake | E28: Milk, cream, sugar, skim milk powder, glucose syrup, emulsifier (mono- and diglycerides of fatty acids), stabilizers (locust bean gum, guar gum, carrageenan), cream cheese (milk, cream, salt, cultures), blueberry swirl (blueberries, sugar, pectin) (8%), graham cracker pieces (whole wheat flour, sugar, honey, soybean oil) | F28: Milk, Wheat | G28: Complete | H28: 1 L | I28: 2/3 cup (95 g) | J28: -18°C | K28: 18 months | L28: Brazil | M28: Paperboard tub with PP lid | N28: Valid | O28: Complete | P28: Complete | Q28: Approved | R28: Approved: All mandatory data complete
A29: FD-TUB-1028 | B29: Ice Cream Tubs | C29: Almond Fudge Ice Cream | D29: Almond Fudge | E29: Milk, cream, sugar, skim milk powder, glucose syrup, emulsifier (mono- and diglycerides of fatty acids), stabilizers (locust bean gum, guar gum, carrageenan), fudge swirl (sugar, glucose syrup, cocoa powder) (8%), roasted almonds (6%) | G29: Complete | H29: 1.5 L | I29: 2/3 cup (95 g) | J29: -18°C | K29: 12 months | L29: Brazil | M29: Paperboard tub with PP lid | N29: Valid | O29: Complete | P29: Incomplete | Q29: Blocked | R29: Blocked: Missing allergen declaration
A30: FD-BAR-1001 | B30: Ice Cream Bars | C30: Chocolate Coated Vanilla Bar | D30: Vanilla | E30: Vanilla ice cream (milk, cream, sugar, skim milk powder, glucose syrup, emulsifier: mono- and diglycerides, stabilizers: locust bean gum, guar gum, natural vanilla flavor) (70%), milk chocolate coating (sugar, cocoa butter, whole milk powder, cocoa mass, coconut oil, emulsifier: soy lecithin, natural vanilla flavor) (30%) | F30: Milk, Soy | G30: Complete | H30: 70 g | I30: 1 bar (70 g) | J30: -20°C | K30: 12 months | L30: United States | M30: Flow-wrap film (individually wrapped) | N30: Valid | O30: Complete | P30: Complete | Q30: Approved | R30: Approved: All mandatory data complete
A31: FD-BAR-1002 | B31: Ice Cream Bars | C31: Almond Chocolate Bar | D31: Vanilla Almond | E31: Vanilla ice cream (milk, cream, sugar, skim milk powder, glucose syrup, emulsifier: mono- and diglycerides, stabilizers: locust bean gum, guar gum, natural vanilla flavor) (68%), milk chocolate coating (sugar, cocoa butter, whole milk powder, cocoa mass, coconut oil, emulsifier: soy lecithin, natural vanilla flavor) (26%), chopped roasted almonds (6%) | F31: Milk, Soy, Tree Nuts (Almond) | G31: Complete | H31: 70 g | I31: 1 bar (70 g) | J31: -18°C | K31: 12 months | L31: United States | M31: Flow-wrap film (individually wrapped) | N31: Valid | O31: Complete | P31: Complete | Q31: Approved | R31: Approved: All mandatory data complete
A32: FD-BAR-1003 | B32: Ice Cream Bars | C32: Salted Caramel Chocolate Bar | D32: Salted Caramel | E32: Vanilla ice cream (milk, cream, sugar, skim milk powder, glucose syrup, emulsifier: mono- and diglycerides, stabilizers: locust bean gum, guar gum, natural vanilla flavor) (60%), caramel sauce (sugar, glucose syrup, cream, butter, sea salt) (12%), milk chocolate coating (sugar, cocoa butter, whole milk powder, cocoa mass, coconut oil, emulsifier: soy lecithin, natural vanilla flavor) (28%) | F32: Milk, Soy | G32: Complete | H32: 80 g | I32: 1 bar (80 g) | J32: -18°C | K32: 18 months | L32: United States | M32: Flow-wrap film (individually wrapped) | N32: Missing | O32: Complete | P32: Incomplete | Q32: Blocked | R32: Blocked: Barcode missing
A33: FD-BAR-1004 | B33: Ice Cream Bars | C33: Double Chocolate Bar | D33: Chocolate | E33: Chocolate ice cream (milk, cream, sugar, cocoa powder, glucose syrup, emulsifier: mono- and diglycerides, stabilizers: guar gum, carrageenan) (70%), dark chocolate coating (sugar, cocoa mass, cocoa butter, coconut oil, emulsifier: soy lecithin) (30%) | G33: Complete | H33: 70 g | I33: 1 bar (70 g) | J33: -18°C | K33: 18 months | L33: Brazil | M33: Flow-wrap film (individually wrapped) | N33: Valid | O33: Complete | P33: Incomplete | Q33: Blocked | R33: Blocked: Missing allergen declaration
A34: FD-BAR-1005 | B34: Ice Cream Bars | C34: White Chocolate Raspberry Bar | D34: Raspberry White Chocolate | E34: Vanilla ice cream (milk, cream, sugar, skim milk powder, glucose syrup, emulsifier: mono- and diglycerides, stabilizers: locust bean gum, guar gum, natural vanilla flavor) (62%), raspberry sauce (raspberries, sugar, pectin) (10%), white chocolate coating (sugar, cocoa butter, whole milk powder, coconut oil, soy lecithin) (28%) | F34: Milk, Soy | G34: Missing | H34: 70 g | I34: 1 bar (70 g) | J34: -18°C | K34: 12 months | L34: Brazil | M34: Flow-wrap film (individually wrapped) | N34: Valid | O34: Complete | P34: Incomplete | Q34: Blocked | R34: Blocked: Missing Nutrition Facts
A35: FD-BAR-1006 | B35: Ice Cream Bars | C35: Cookies & Cream Bar | D35: Cookies & Cream | E35: Vanilla ice cream (milk, cream, sugar, skim milk powder, glucose syrup, emulsifier: mono- and diglycerides, stabilizers: locust bean gum, guar gum, natural vanilla flavor) (60%), milk chocolate coating (sugar, cocoa butter, whole milk powder, cocoa mass, coconut oil, emulsifier: soy lecithin, natural vanilla flavor) (30%), chocolate cookie crumbs (wheat flour, sugar, palm oil, cocoa powder, salt) (10%) | F35: Milk, Wheat, Soy | G35: Missing | H35: 70 g | I35: 1 bar (70 g) | J35: -18°C | K35: 18 months | L35: United States | M35: Flow-wrap film (individually wrapped) | N35: Valid | O35: Complete | P35: Incomplete | Q35: Blocked | R35: Blocked: Missing Nutrition Facts
A36: FD-BAR-1007 | B36: Ice Cream Bars | C36: Strawberry Fruit Bar | D36: Strawberry | E36: Strawberries (45%), water, sugar, glucose syrup, lemon juice concentrate, stabilizer (guar gum), beet juice concentrate (color) | F36: None | G36: Complete | H36: 60 g | I36: 1 bar (60 g) | J36: -18°C | L36: Canada | M36: Flow-wrap film (individually wrapped) | N36: Valid | O36: Complete | P36: Complete | Q36: Warning | R36: Warning: Shelf life missing
A37: FD-BAR-1008 | B37: Ice Cream Bars | C37: Mango Fruit Bar | D37: Mango | E37: Mango puree (48%), water, sugar, glucose syrup, lime juice concentrate, stabilizer (locust bean gum) | F37: None | G37: Complete | H37: 60 g | I37: 1 bar (60 g) | J37: -18°C | K37: 15 months | L37: United Kingdom | M37: Flow-wrap film (individually wrapped) | N37: Valid | O37: Complete | P37: Complete | Q37: Approved | R37: Approved: All mandatory data complete
A38: FD-BAR-1009 | B38: Ice Cream Bars | C38: Coconut Dark Chocolate Bar | D38: Coconut | E38: Coconut frozen dessert (coconut cream, water, sugar, tapioca syrup, guar gum) (68%), dark chocolate coating (sugar, cocoa mass, cocoa butter, coconut oil, emulsifier: soy lecithin) (32%) | F38: Soy | G38: Complete | H38: 70 g | I38: 1 bar (70 g) | J38: -18°C | K38: 18 months | L38: United States | M38: Flow-wrap film (individually wrapped) | N38: Valid | O38: Complete | P38: Complete | Q38: Approved | R38: Approved: All mandatory data complete
A39: FD-BAR-1010 | B39: Ice Cream Bars | C39: Pistachio Chocolate Bar | D39: Pistachio | E39: Pistachio ice cream (milk, cream, sugar, pistachio paste, glucose syrup, stabilizers: guar gum, locust bean gum) (68%), milk chocolate coating (sugar, cocoa butter, whole milk powder, cocoa mass, coconut oil, emulsifier: soy lecithin, natural vanilla flavor) (26%), chopped pistachios (6%) | F39: Milk, Soy, Tree Nuts (Pistachio) | G39: Complete | H39: 70 g | I39: 1 bar (70 g) | J39: -18°C | K39: 12 months | L39: United States | M39: Flow-wrap film (individually wrapped) | N39: Valid | O39: Complete | P39: Complete | Q39: Approved | R39: Approved: All mandatory data complete
A40: FD-BAR-1011 | B40: Ice Cream Bars | C40: Coffee Mocha Bar | D40: Coffee Mocha | E40: Coffee ice cream (milk, cream, sugar, coffee extract, glucose syrup, stabilizers: guar gum, carrageenan) (70%), dark chocolate coating (sugar, cocoa mass, cocoa butter, coconut oil, emulsifier: soy lecithin) (30%) | F40: Milk, Soy | G40: Complete | H40: 80 g | I40: 1 bar (80 g) | J40: -18°C | K40: 15 months | L40: Brazil | M40: Flow-wrap film (individually wrapped) | N40: Valid | O40: Complete | P40: Complete | Q40: Approved | R40: Approved: All mandatory data complete
...

Sheet Validation_Summary
A1: Launch Status | B1: Product Count | C1: % of Total | E1: Validation Result | F1: Launch Status | G1: Product Count | H1: % of Total
A2: Approved | B2: =COUNTIF(Product_Audit!$Q$2:$Q$91,A2) -> 48 | C2: =B2/COUNTA(Product_Audit!$A$2:$A$91) -> 0.53333333 | E2: Approved: All mandatory data complete | F2: Approved | G2: =COUNTIF(Product_Audit!$R$2:$R$91,E2) -> 48 | H2: =G2/COUNTA(Product_Audit!$A$2:$A$91) -> 0.53333333
A3: Warning | B3: =COUNTIF(Product_Audit!$Q$2:$Q$91,A3) -> 18 | C3: =B3/COUNTA(Product_Audit!$A$2:$A$91) -> 0.2 | E3: Blocked: Missing allergen declaration | F3: Blocked | G3: =COUNTIF(Product_Audit!$R$2:$R$91,E3) -> 5 | H3: =G3/COUNTA(Product_Audit!$A$2:$A$91) -> 0.055555556
A4: Blocked | B4: =COUNTIF(Product_Audit!$Q$2:$Q$91,A4) -> 24 | C4: =B4/COUNTA(Product_Audit!$A$2:$A$91) -> 0.26666667 | E4: Blocked: Missing Nutrition Facts | F4: Blocked | G4: =COUNTIF(Product_Audit!$R$2:$R$91,E4) -> 5 | H4: =G4/COUNTA(Product_Audit!$A$2:$A$91) -> 0.055555556
E5: Blocked: Missing ingredient list | F5: Blocked | G5: =COUNTIF(Product_Audit!$R$2:$R$91,E5) -> 4 | H5: =G5/COUNTA(Product_Audit!$A$2:$A$91) -> 0.044444444
E6: Blocked: Net weight missing | F6: Blocked | G6: =COUNTIF(Product_Audit!$R$2:$R$91,E6) -> 3 | H6: =G6/COUNTA(Product_Audit!$A$2:$A$91) -> 0.033333333
E7: Blocked: Mandatory attributes missing | F7: Blocked | G7: =COUNTIF(Product_Audit!$R$2:$R$91,E7) -> 3 | H7: =G7/COUNTA(Product_Audit!$A$2:$A$91) -> 0.033333333
E8: Blocked: Barcode missing | F8: Blocked | G8: =COUNTIF(Product_Audit!$R$2:$R$91,E8) -> 4 | H8: =G8/COUNTA(Product_Audit!$A$2:$A$91) -> 0.044444444
E9: Warning: Shelf life missing | F9: Warning | G9: =COUNTIF(Product_Audit!$R$2:$R$91,E9) -> 5 | H9: =G9/COUNTA(Product_Audit!$A$2:$A$91) -> 0.055555556
E10: Warning: Serving size inconsistent | F10: Warning | G10: =COUNTIF(Product_Audit!$R$2:$R$91,E10) -> 5 | H10: =G10/COUNTA(Product_Audit!$A$2:$A$91) -> 0.055555556
E11: Warning: Product description incomplete | F11: Warning | G11: =COUNTIF(Product_Audit!$R$2:$R$91,E11) -> 4 | H11: =G11/COUNTA(Product_Audit!$A$2:$A$91) -> 0.044444444
E12: Warning: Packaging information missing | F12: Warning | G12: =COUNTIF(Product_Audit!$R$2:$R$91,E12) -> 4 | H12: =G12/COUNTA(Product_Audit!$A$2:$A$91) -> 0.044444444

Sheet Category_Summary
A1: Category | B1: Total Products | C1: Approved | D1: Warning | E1: Blocked | F1: Blocked % | G1: Launch-Ready %
A2: Ice Cream Tubs | B2: =COUNTIF(Product_Audit!$B$2:$B$91,A2) -> 28 | C2: =COUNTIFS(Product_Audit!$B$2:$B$91,$A2,Product_Audit!$Q$2:$Q$91,"Approved") -> 15 | D2: =COUNTIFS(Product_Audit!$B$2:$B$91,$A2,Product_Audit!$Q$2:$Q$91,"Warning") -> 6 | E2: =COUNTIFS(Product_Audit!$B$2:$B$91,$A2,Product_Audit!$Q$2:$Q$91,"Blocked") -> 7 | F2: =IF(B2=0,0,E2/B2) -> 0.25 | G2: =IF(B2=0,0,C2/B2) -> 0.53571429
A3: Ice Cream Bars | B3: =COUNTIF(Product_Audit!$B$2:$B$91,A3) -> 18 | C3: =COUNTIFS(Product_Audit!$B$2:$B$91,$A3,Product_Audit!$Q$2:$Q$91,"Approved") -> 10 | D3: =COUNTIFS(Product_Audit!$B$2:$B$91,$A3,Product_Audit!$Q$2:$Q$91,"Warning") -> 3 | E3: =COUNTIFS(Product_Audit!$B$2:$B$91,$A3,Product_Audit!$Q$2:$Q$91,"Blocked") -> 5 | F3: =IF(B3=0,0,E3/B3) -> 0.27777778 | G3: =IF(B3=0,0,C3/B3) -> 0.55555556
A4: Frozen Cakes & Tortes | B4: =COUNTIF(Product_Audit!$B$2:$B$91,A4) -> 16 | C4: =COUNTIFS(Product_Audit!$B$2:$B$91,$A4,Product_Audit!$Q$2:$Q$91,"Approved") -> 8 | D4: =COUNTIFS(Product_Audit!$B$2:$B$91,$A4,Product_Audit!$Q$2:$Q$91,"Warning") -> 3 | E4: =COUNTIFS(Product_Audit!$B$2:$B$91,$A4,Product_Audit!$Q$2:$Q$91,"Blocked") -> 5 | F4: =IF(B4=0,0,E4/B4) -> 0.3125 | G4: =IF(B4=0,0,C4/B4) -> 0.5
A5: Frozen Cheesecakes | B5: =COUNTIF(Product_Audit!$B$2:$B$91,A5) -> 12 | C5: =COUNTIFS(Product_Audit!$B$2:$B$91,$A5,Product_Audit!$Q$2:$Q$91,"Approved") -> 6 | D5: =COUNTIFS(Product_Audit!$B$2:$B$91,$A5,Product_Audit!$Q$2:$Q$91,"Warning") -> 3 | E5: =COUNTIFS(Product_Audit!$B$2:$B$91,$A5,Product_Audit!$Q$2:$Q$91,"Blocked") -> 3 | F5: =IF(B5=0,0,E5/B5) -> 0.25 | G5: =IF(B5=0,0,C5/B5) -> 0.5
A6: Frozen Dessert Cups | B6: =COUNTIF(Product_Audit!$B$2:$B$91,A6) -> 10 | C6: =COUNTIFS(Product_Audit!$B$2:$B$91,$A6,Product_Audit!$Q$2:$Q$91,"Approved") -> 5 | D6: =COUNTIFS(Product_Audit!$B$2:$B$91,$A6,Product_Audit!$Q$2:$Q$91,"Warning") -> 2 | E6: =COUNTIFS(Product_Audit!$B$2:$B$91,$A6,Product_Audit!$Q$2:$Q$91,"Blocked") -> 3 | F6: =IF(B6=0,0,E6/B6) -> 0.3 | G6: =IF(B6=0,0,C6/B6) -> 0.5
A7: Frozen Mousses | B7: =COUNTIF(Product_Audit!$B$2:$B$91,A7) -> 6 | C7: =COUNTIFS(Product_Audit!$B$2:$B$91,$A7,Product_Audit!$Q$2:$Q$91,"Approved") -> 4 | D7: =COUNTIFS(Product_Audit!$B$2:$B$91,$A7,Product_Audit!$Q$2:$Q$91,"Warning") -> 1 | E7: =COUNTIFS(Product_Audit!$B$2:$B$91,$A7,Product_Audit!$Q$2:$Q$91,"Blocked") -> 1 | F7: =IF(B7=0,0,E7/B7) -> 0.16666667 | G7: =IF(B7=0,0,C7/B7) -> 0.66666667
